Workbook
Name Slicer_campaign_name: #N/A

Sheet Cohort
A1: Distinct Count of id_customer | B1: Column Labels
B2: 2022 | N2: 2023
A3: Row Labels | B3: yan | C3: fev | D3: mar | E3: apr | F3: may | G3: iyn | H3: iyl | I3: avq | J3: sen | K3: okt | L3: noy | M3: dek | N3: yan | O3: fev | P3: mar | Q3: apr
A4: YeniMusteriSayi | B4: 117 | C4: 85 | D4: 85 | E4: 94 | F4: 100 | G4: 119 | H4: 113 | I4: 143 | J4: 122 | K4: 137 | L4: 125 | M4: 132 | N4: 136 | O4: 112 | P4: 130 | Q4: 134
A5: 1 | B5: 56 | C5: 58 | D5: 49 | E5: 69 | F5: 53 | G5: 86 | H5: 73 | I5: 103 | J5: 96 | K5: 108 | L5: 105 | M5: 106 | N5: 119 | O5: 109 | P5: 128 | Q5: 133
A6: 2 | B6: 86 | C6: 58 | D6: 64 | E6: 72 | F6: 88 | G6: 93 | H6: 87 | I6: 130 | J6: 101 | K6: 132 | L6: 115 | M6: 124 | N6: 135 | O6: 110 | P6: 130
A7: 3 | B7: 76 | C7: 58 | D7: 62 | E7: 78 | F7: 83 | G7: 90 | H7: 93 | I7: 124 | J7: 107 | K7: 120 | L7: 117 | M7: 128 | N7: 133 | O7: 112
A8: 4 | B8: 76 | C8: 62 | D8: 73 | E8: 69 | F8: 70 | G8: 105 | H8: 91 | I8: 125 | J8: 110 | K8: 125 | L8: 117 | M8: 129 | N8: 134
A9: 5 | B9: 77 | C9: 65 | D9: 56 | E9: 73 | F9: 78 | G9: 103 | H9: 100 | I9: 124 | J9: 108 | K9: 132 | L9: 115 | M9: 126
A10: 6 | B10: 79 | C10: 54 | D10: 61 | E10: 78 | F10: 81 | G10: 90 | H10: 90 | I10: 116 | J10: 113 | K10: 129 | L10: 113
A11: 7 | B11: 84 | C11: 64 | D11: 67 | E11: 75 | F11: 79 | G11: 97 | H11: 86 | I11: 125 | J11: 104 | K11: 126
A12: 8 | B12: 74 | C12: 64 | D12: 63 | E12: 68 | F12: 83 | G12: 93 | H12: 99 | I12: 118 | J12: 110
A13: 9 | B13: 80 | C13: 60 | D13: 63 | E13: 71 | F13: 80 | G13: 101 | H13: 91 | I13: 130
A14: 10 | B14: 83 | C14: 66 | D14: 55 | E14: 77 | F14: 86 | G14: 91 | H14: 96
A15: 11 | B15: 87 | C15: 61 | D15: 68 | E15: 80 | F15: 80 | G15: 98
A16: 12 | B16: 78 | C16: 62 | D16: 70 | E16: 68 | F16: 82
A17: 13 | B17: 75 | C17: 62 | D17: 60 | E17: 75
A18: 14 | B18: 86 | C18: 59 | D18: 57
A19: 15 | B19: 84 | C19: 69
A20: 16 | B20: 77
S21: Ortalama Geridonus
B22: {=INDEX(B4:B20,COUNTA(B4:B20))} -> 77 | C22: {=INDEX(C4:C20,COUNTA(C4:C20))} -> 69 | D22: {=INDEX(D4:D20,COUNTA(D4:D20))} -> 57 | E22: {=INDEX(E4:E20,COUNTA(E4:E20))} -> 75 | F22: {=INDEX(F4:F20,COUNTA(F4:F20))} -> 82 | G22: {=INDEX(G4:G20,COUNTA(G4:G20))} -> 98 | H22: {=INDEX(H4:H20,COUNTA(H4:H20))} -> 96 | I22: {=INDEX(I4:I20,COUNTA(I4:I20))} -> 130 | ... Q22: {=INDEX(Q4:Q20,COUNTA(Q4:Q20))} -> 133 | S22: =AVERAGE(B22:Q22) -> 104.25
A25: Distinct Count of id_customer | B25: Column Labels
B26: 2022 | N26: 2023
A27: Row Labels | B27: yan | C27: fev | D27: mar | E27: apr | F27: may | G27: iyn | H27: iyl | I27: avq | J27: sen | K27: okt | L27: noy | M27: dek | N27: yan | O27: fev | P27: mar | Q27: apr
A28: YeniMusteriSayi | B28: 1 | C28: 1 | D28: 1 | E28: 1 | F28: 1 | G28: 1 | H28: 1 | I28: 1 | J28: 1 | K28: 1 | L28: 1 | M28: 1 | N28: 1 | O28: 1 | P28: 1 | Q28: 1
A29: 1 | B29: 0.47863248 | C29: 0.68235294 | D29: 0.57647059 | E29: 0.73404255 | F29: 0.53 | G29: 0.72268908 | H29: 0.6460177 | I29: 0.72027972 | J29: 0.78688525 | K29: 0.78832117 | L29: 0.84 | M29: 0.8030303 | N29: 0.875 | O29: 0.97321429 | P29: 0.98461538 | Q29: 0.99253731
A30: 2 | B30: 0.73504274 | C30: 0.68235294 | D30: 0.75294118 | E30: 0.76595745 | F30: 0.88 | G30: 0.78151261 | H30: 0.7699115 | I30: 0.90909091 | J30: 0.82786885 | K30: 0.96350365 | L30: 0.92 | M30: 0.93939394 | N30: 0.99264706 | O30: 0.98214286 | P30: 1
A31: 3 | B31: 0.64957265 | C31: 0.68235294 | D31: 0.72941176 | E31: 0.82978723 | F31: 0.83 | G31: 0.75630252 | H31: 0.82300885 | I31: 0.86713287 | J31: 0.87704918 | K31: 0.87591241 | L31: 0.936 | M31: 0.96969697 | N31: 0.97794118 | O31: 1
A32: 4 | B32: 0.64957265 | C32: 0.72941176 | D32: 0.85882353 | E32: 0.73404255 | F32: 0.7 | G32: 0.88235294 | H32: 0.80530973 | I32: 0.87412587 | J32: 0.90163934 | K32: 0.91240876 | L32: 0.936 | M32: 0.97727273 | N32: 0.98529412
A33: 5 | B33: 0.65811966 | C33: 0.76470588 | D33: 0.65882353 | E33: 0.77659574 | F33: 0.78 | G33: 0.86554622 | H33: 0.88495575 | I33: 0.86713287 | J33: 0.8852459 | K33: 0.96350365 | L33: 0.92 | M33: 0.95454545
A34: 6 | B34: 0.67521368 | C34: 0.63529412 | D34: 0.71764706 | E34: 0.82978723 | F34: 0.81 | G34: 0.75630252 | H34: 0.79646018 | I34: 0.81118881 | J34: 0.92622951 | K34: 0.94160584 | L34: 0.904
A35: 7 | B35: 0.71794872 | C35: 0.75294118 | D35: 0.78823529 | E35: 0.79787234 | F35: 0.79 | G35: 0.81512605 | H35: 0.76106195 | I35: 0.87412587 | J35: 0.85245902 | K35: 0.91970803
A36: 8 | B36: 0.63247863 | C36: 0.75294118 | D36: 0.74117647 | E36: 0.72340426 | F36: 0.83 | G36: 0.78151261 | H36: 0.87610619 | I36: 0.82517483 | J36: 0.90163934
A37: 9 | B37: 0.68376068 | C37: 0.70588235 | D37: 0.74117647 | E37: 0.75531915 | F37: 0.8 | G37: 0.8487395 | H37: 0.80530973 | I37: 0.90909091
A38: 10 | B38: 0.70940171 | C38: 0.77647059 | D38: 0.64705882 | E38: 0.81914894 | F38: 0.86 | G38: 0.76470588 | H38: 0.84955752
A39: 11 | B39: 0.74358974 | C39: 0.71764706 | D39: 0.8 | E39: 0.85106383 | F39: 0.8 | G39: 0.82352941
A40: 12 | B40: 0.66666667 | C40: 0.72941176 | D40: 0.82352941 | E40: 0.72340426 | F40: 0.82
A41: 13 | B41: 0.64102564 | C41: 0.72941176 | D41: 0.70588235 | E41: 0.79787234
A42: 14 | B42: 0.73504274 | C42: 0.69411765 | D42: 0.67058824
...

Sheet Stabillik
B1: 2023-cü il
A2: Kompaniyalar | B2: yan | C2: fev | D2: mar | E2: apr | F2: may | G2: Stabillik
A3: RespondsToMailOffers | B3: 1836 | C3: 2295 | D3: 2808 | E3: 2997 | F3: 3132 | G3: 0.20601671
A4: ChildrenInHH | B4: 680 | C4: 790 | D4: 870 | E4: 1050 | F4: 1040 | G4: 0.18069269
A5: TruckOwner | B5: 1690 | C5: 1846 | D5: 2366 | E5: 2444 | F5: 2496 | G5: 0.17180208
A6: MaritalStatus | B6: 2146 | C6: 2523 | D6: 2900 | E6: 3103 | F6: 3306 | G6: 0.16607233
A7: HandsetWebCapable | B7: 5022 | C7: 5518 | D7: 6200 | E7: 6944 | F7: 6944 | G7: 0.13977143
A8: NotNewCellphoneUser | B8: 2324 | C8: 2548 | D8: 3024 | E8: 3024 | F8: 3192 | G8: 0.13037239
A9: OwnsMotorcycle | B9: 924 | C9: 1106 | D9: 1232 | E9: 1274 | F9: 1274 | G9: 0.12892129
A10: HasCreditCard | B10: 4745 | C10: 5135 | D10: 5655 | E10: 6240 | F10: 6435 | G10: 0.1268328
A11: MadeCallToRetentionTeam | B11: 1280 | C11: 1264 | D11: 1600 | E11: 1600 | F11: 1616 | G11: 0.12417021
A12: BuysViaMailOrder | B12: 1700 | C12: 1700 | D12: 1975 | E12: 2050 | F12: 2250 | G12: 0.12243264
A13: RVOwner | B13: 1848 | C13: 2046 | D13: 2288 | E13: 2398 | F13: 2486 | G13: 0.1185781
A14: OwnsComputer | B14: 5022 | C14: 5084 | D14: 5952 | E14: 6200 | F14: 6324 | G14: 0.10856828
... A19: NewCellphoneUser | B19: 2100 | C19: 2300 | D19: 2450 | E19: 2375 | F19: 2525 | G19: 0.069353217

Sheet Pareto
A1: Row Labels | B1: Total | C1: %
A2: cam10 | B2: 65010 | C2: 0.12669699
A3: cam09 | B3: 60825 | C3: 0.2452379
A4: cam12 | B4: 57980 | C4: 0.35823423
A5: cam11 | B5: 56606 | C5: 0.4685528
A6: cam03 | B6: 55738 | C6: 0.57717973
A7: cam14 | B7: 26908 | C7: 0.62962032
A8: cam13 | B8: 23350 | C8: 0.67512677
A9: cam05 | B9: 22352 | C9: 0.71868824
A10: cam02 | B10: 20852 | C10: 0.75932639
A11: cam17 | B11: 20503 | C11: 0.79928437
A12: cam04 | B12: 20254 | C12: 0.83875708
A13: cam07 | B13: 18925 | C13: 0.87563972
... A18: cam01 | B18: 6700 | C18: 1

Sheet pivot
A1: full_name | B1: campaign_name | C1: Max of join_date | D1: Average of Qiymet | F1: Ad
A2: Abbott Salazar | B2: HandsetWebCapable | C2: 44725 | D2: 62
A3: Abbott Salazar | B3: NewCellphoneUser | C3: 45009 | D3: 25
A4: Abdul Foulds | B4: BuysViaMailOrder | C4: 44943 | D4: 25
A5: Abdul Foulds | B5: MadeCallToRetentionTeam | C5: 44798 | D5: 16
A6: Abrahan Cotton | B6: MaritalStatus | C6: 44921 | D6: 29
A7: Abrahan Cotton | B7: RespondsToMailOffers | C7: 44992 | D7: 27
A8: Adan Doghartie | B8: NonUSTravel | C8: 44576 | D8: 66
A9: Adan Doghartie | B9: HandsetRefurbished | C9: 44961 | D9: 26
A10: Addie Chillcot | B10: NonUSTravel | C10: 44589 | D10: 66
A11: Addie Chillcot | B11: BuysViaMailOrder | C11: 44717 | D11: 25
A12: Adelle Wattingham | B12: OwnsMotorcycle | C12: 44905 | D12: 14
A13: Adey Driscoll | B13: BuysViaMailOrder | C13: 44586 | D13: 25
... A1946: Zenia Ruecastle | B1946: NewCellphoneUser | C1946: 45032 | D1946: 25

Sheet endirim
B3: Müştəri adı | C3: Son kampaniya | D3: Son kampaniya qiyməti | E3: Ən baha kompaniya | F3: Ən baha qiymət | G3: Nəticə
B4: Abbott Salazar | C4: {=_xlfn.XLOOKUP(1,(pivot!$A$2:$A$1946=Table3[[#This Row],[Müştəri adı]])*(pivot!$C$2:$C$1946=_xlfn.MAXIFS(pivot!$C$2:$C$1946,pivot!$A$2:$A$1946,Table3[[#This Row],[Müştəri adı]])),pivot!$B$2:$B$1946)} -> NewCellphoneUser | D4: {=_xlfn.XLOOKUP(1, (pivot!$A$2:$A$1946=endirim!B4) * (pivot!$C$2:$C$1946 = _xlfn.MAXIFS(pivot!$C$2:$C$1946, pivot!$A$2:$A$1946, endirim!B4)), pivot!$D$2:$D$1946)} -> 25 | E4: {=_xlfn.XLOOKUP(1, (pivot!$A$2:$A$1946=endirim!B4) * (pivot!$D$2:$D$1946 = _xlfn.MAXIFS(pivot!$D$2:$D$1946, pivot!$A$2:$A$1946, endirim!B4)), pivot!$B$2:$B$1946)} -> HandsetWebCapable | F4: =_xlfn.MAXIFS(pivot!$D$2:$D$1946, pivot!$A$2:$A$1946, endirim!B4) -> 62 | G4: =IF(D4=F4, "Təklif yoxdur", E4&" Kompaniyasını 20% endirimlə təklif et") -> HandsetWebCapable Kompaniyasını 20% endirimlə təklif et
B5: Abdul Foulds | C5: {=_xlfn.XLOOKUP(1,(pivot!$A$2:$A$1946=Table3[[#This Row],[Müştəri adı]])*(pivot!$C$2:$C$1946=_xlfn.MAXIFS(pivot!$C$2:$C$1946,pivot!$A$2:$A$1946,Table3[[#This Row],[Müştəri adı]])),pivot!$B$2:$B$1946)} -> BuysViaMailOrder | D5: {=_xlfn.XLOOKUP(1, (pivot!$A$2:$A$1946=endirim!B5) * (pivot!$C$2:$C$1946 = _xlfn.MAXIFS(pivot!$C$2:$C$1946, pivot!$A$2:$A$1946, endirim!B5)), pivot!$D$2:$D$1946)} -> 25 | E5: {=_xlfn.XLOOKUP(1, (pivot!$A$2:$A$1946=endirim!B5) * (pivot!$D$2:$D$1946 = _xlfn.MAXIFS(pivot!$D$2:$D$1946, pivot!$A$2:$A$1946, endirim!B5)), pivot!$B$2:$B$1946)} -> BuysViaMailOrder | F5: =_xlfn.MAXIFS(pivot!$D$2:$D$1946, pivot!$A$2:$A$1946, endirim!B5) -> 25 | G5: =IF(D5=F5, "Təklif yoxdur", E5&" Kompaniyasını 20% endirimlə təklif et") -> Təklif yoxdur
B6: Abrahan Cotton | C6: {=_xlfn.XLOOKUP(1,(pivot!$A$2:$A$1946=Table3[[#This Row],[Müştəri adı]])*(pivot!$C$2:$C$1946=_xlfn.MAXIFS(pivot!$C$2:$C$1946,pivot!$A$2:$A$1946,Table3[[#This Row],[Müştəri adı]])),pivot!$B$2:$B$1946)} -> RespondsToMailOffers | D6: {=_xlfn.XLOOKUP(1, (pivot!$A$2:$A$1946=endirim!B6) * (pivot!$C$2:$C$1946 = _xlfn.MAXIFS(pivot!$C$2:$C$1946, pivot!$A$2:$A$1946, endirim!B6)), pivot!$D$2:$D$1946)} -> 27 | E6: {=_xlfn.XLOOKUP(1, (pivot!$A$2:$A$1946=endirim!B6) * (pivot!$D$2:$D$1946 = _xlfn.MAXIFS(pivot!$D$2:$D$1946, pivot!$A$2:$A$1946, endirim!B6)), pivot!$B$2:$B$1946)} -> MaritalStatus | F6: =_xlfn.MAXIFS(pivot!$D$2:$D$1946, pivot!$A$2:$A$1946, endirim!B6) -> 29 | G6: =IF(D6=F6, "Təklif yoxdur", E6&" Kompaniyasını 20% endirimlə təklif et") -> MaritalStatus Kompaniyasını 20% endirimlə təklif et
B7: Adan Doghartie | C7: {=_xlfn.XLOOKUP(1,(pivot!$A$2:$A$1946=Table3[[#This Row],[Müştəri adı]])*(pivot!$C$2:$C$1946=_xlfn.MAXIFS(pivot!$C$2:$C$1946,pivot!$A$2:$A$1946,Table3[[#This Row],[Müştəri adı]])),pivot!$B$2:$B$1946)} -> HandsetRefurbished | D7: {=_xlfn.XLOOKUP(1, (pivot!$A$2:$A$1946=endirim!B7) * (pivot!$C$2:$C$1946 = _xlfn.MAXIFS(pivot!$C$2:$C$1946, pivot!$A$2:$A$1946, endirim!B7)), pivot!$D$2:$D$1946)} -> 26 | E7: {=_xlfn.XLOOKUP(1, (pivot!$A$2:$A$1946=endirim!B7) * (pivot!$D$2:$D$1946 = _xlfn.MAXIFS(pivot!$D$2:$D$1946, pivot!$A$2:$A$1946, endirim!B7)), pivot!$B$2:$B$1946)} -> NonUSTravel | F7: =_xlfn.MAXIFS(pivot!$D$2:$D$1946, pivot!$A$2:$A$1946, endirim!B7) -> 66 | G7: =IF(D7=F7, "Təklif yoxdur", E7&" Kompaniyasını 20% endirimlə təklif et") -> NonUSTravel Kompaniyasını 20% endirimlə təklif et
B8: Addie Chillcot | C8: {=_xlfn.XLOOKUP(1,(pivot!$A$2:$A$1946=Table3[[#This Row],[Müştəri adı]])*(pivot!$C$2:$C$1946=_xlfn.MAXIFS(pivot!$C$2:$C$1946,pivot!$A$2:$A$1946,Table3[[#This Row],[Müştəri adı]])),pivot!$B$2:$B$1946)} -> BuysViaMailOrder | D8: {=_xlfn.XLOOKUP(1, (pivot!$A$2:$A$1946=endirim!B8) * (pivot!$C$2:$C$1946 = _xlfn.MAXIFS(pivot!$C$2:$C$1946, pivot!$A$2:$A$1946, endirim!B8)), pivot!$D$2:$D$1946)} -> 25 | E8: {=_xlfn.XLOOKUP(1, (pivot!$A$2:$A$1946=endirim!B8) * (pivot!$D$2:$D$1946 = _xlfn.MAXIFS(pivot!$D$2:$D$1946, pivot!$A$2:$A$1946, endirim!B8)), pivot!$B$2:$B$1946)} -> NonUSTravel | F8: =_xlfn.MAXIFS(pivot!$D$2:$D$1946, pivot!$A$2:$A$1946, endirim!B8) -> 66 | G8: =IF(D8=F8, "Təklif yoxdur", E8&" Kompaniyasını 20% endirimlə təklif et") -> NonUSTravel Kompaniyasını 20% endirimlə təklif et
B9: Adelle Wattingham | C9: {=_xlfn.XLOOKUP(1,(pivot!$A$2:$A$1946=Table3[[#This Row],[Müştəri adı]])*(pivot!$C$2:$C$1946=_xlfn.MAXIFS(pivot!$C$2:$C$1946,pivot!$A$2:$A$1946,Table3[[#This Row],[Müştəri adı]])),pivot!$B$2:$B$1946)} -> OwnsMotorcycle | D9: {=_xlfn.XLOOKUP(1, (pivot!$A$2:$A$1946=endirim!B9) * (pivot!$C$2:$C$1946 = _xlfn.MAXIFS(pivot!$C$2:$C$1946, pivot!$A$2:$A$1946, endirim!B9)), pivot!$D$2:$D$1946)} -> 14 | E9: {=_xlfn.XLOOKUP(1, (pivot!$A$2:$A$1946=endirim!B9) * (pivot!$D$2:$D$1946 = _xlfn.MAXIFS(pivot!$D$2:$D$1946, pivot!$A$2:$A$1946, endirim!B9)), pivot!$B$2:$B$1946)} -> OwnsMotorcycle | F9: =_xlfn.MAXIFS(pivot!$D$2:$D$1946, pivot!$A$2:$A$1946, endirim!B9) -> 14 | G9: =IF(D9=F9, "Təklif yoxdur", E9&" Kompaniyasını 20% endirimlə təklif et") -> Təklif yoxdur
B10: Adey Driscoll | C10: {=_xlfn.XLOOKUP(1,(pivot!$A$2:$A$1946=Table3[[#This Row],[Müştəri adı]])*(pivot!$C$2:$C$1946=_xlfn.MAXIFS(pivot!$C$2:$C$1946,pivot!$A$2:$A$1946,Table3[[#This Row],[Müştəri adı]])),pivot!$B$2:$B$1946)} -> RVOwner | D10: {=_xlfn.XLOOKUP(1, (pivot!$A$2:$A$1946=endirim!B10) * (pivot!$C$2:$C$1946 = _xlfn.MAXIFS(pivot!$C$2:$C$1946, pivot!$A$2:$A$1946, endirim!B10)), pivot!$D$2:$D$1946)} -> 22 | E10: {=_xlfn.XLOOKUP(1, (pivot!$A$2:$A$1946=endirim!B10) * (pivot!$D$2:$D$1946 = _xlfn.MAXIFS(pivot!$D$2:$D$1946, pivot!$A$2:$A$1946, endirim!B10)), pivot!$B$2:$B$1946)} -> BuysViaMailOrder | F10: =_xlfn.MAXIFS(pivot!$D$2:$D$1946, pivot!$A$2:$A$1946, endirim!B10) -> 25 | G10: =IF(D10=F10, "Təklif yoxdur", E10&" Kompaniyasını 20% endirimlə təklif et") -> BuysViaMailOrder Kompaniyasını 20% endirimlə təklif et
B11: Adler Instock | C11: {=_xlfn.XLOOKUP(1,(pivot!$A$2:$A$1946=Table3[[#This Row],[Müştəri adı]])*(pivot!$C$2:$C$1946=_xlfn.MAXIFS(pivot!$C$2:$C$1946,pivot!$A$2:$A$1946,Table3[[#This Row],[Müştəri adı]])),pivot!$B$2:$B$1946)} -> ChildrenInHH | D11: {=_xlfn.XLOOKUP(1, (pivot!$A$2:$A$1946=endirim!B11) * (pivot!$C$2:$C$1946 = _xlfn.MAXIFS(pivot!$C$2:$C$1946, pivot!$A$2:$A$1946, endirim!B11)), pivot!$D$2:$D$1946)} -> 10 | E11: {=_xlfn.XLOOKUP(1, (pivot!$A$2:$A$1946=endirim!B11) * (pivot!$D$2:$D$1946 = _xlfn.MAXIFS(pivot!$D$2:$D$1946, pivot!$A$2:$A$1946, endirim!B11)), pivot!$B$2:$B$1946)} -> ChildrenInHH | F11: =_xlfn.MAXIFS(pivot!$D$2:$D$1946, pivot!$A$2:$A$1946, endirim!B11) -> 10 | G11: =IF(D11=F11, "Təklif yoxdur", E11&" Kompaniyasını 20% endirimlə təklif et") -> Təklif yoxdur
B12: Adolph Wisedale | C12: {=_xlfn.XLOOKUP(1,(pivot!$A$2:$A$1946=Table3[[#This Row],[Müştəri adı]])*(pivot!$C$2:$C$1946=_xlfn.MAXIFS(pivot!$C$2:$C$1946,pivot!$A$2:$A$1946,Table3[[#This Row],[Müştəri adı]])),pivot!$B$2:$B$1946)} -> OwnsComputer | D12: {=_xlfn.XLOOKUP(1, (pivot!$A$2:$A$1946=endirim!B12) * (pivot!$C$2:$C$1946 = _xlfn.MAXIFS(pivot!$C$2:$C$1946, pivot!$A$2:$A$1946, endirim!B12)), pivot!$D$2:$D$1946)} -> 62 | E12: {=_xlfn.XLOOKUP(1, (pivot!$A$2:$A$1946=endirim!B12) * (pivot!$D$2:$D$1946 = _xlfn.MAXIFS(pivot!$D$2:$D$1946, pivot!$A$2:$A$1946, endirim!B12)), pivot!$B$2:$B$1946)} -> OwnsComputer | F12: =_xlfn.MAXIFS(pivot!$D$2:$D$1946, pivot!$A$2:$A$1946, endirim!B12) -> 62 | G12: =IF(D12=F12, "Təklif yoxdur", E12&" Kompaniyasını 20% endirimlə təklif et") -> Təklif yoxdur
B13: Adoree Hasard | C13: {=_xlfn.XLOOKUP(1,(pivot!$A$2:$A$1946=Table3[[#This Row],[Müştəri adı]])*(pivot!$C$2:$C$1946=_xlfn.MAXIFS(pivot!$C$2:$C$1946,pivot!$A$2:$A$1946,Table3[[#This Row],[Müştəri adı]])),pivot!$B$2:$B$1946)} -> HandsetWebCapable | D13: {=_xlfn.XLOOKUP(1, (pivot!$A$2:$A$1946=endirim!B13) * (pivot!$C$2:$C$1946 = _xlfn.MAXIFS(pivot!$C$2:$C$1946, pivot!$A$2:$A$1946, endirim!B13)), pivot!$D$2:$D$1946)} -> 62 | E13: {=_xlfn.XLOOKUP(1, (pivot!$A$2:$A$1946=endirim!B13) * (pivot!$D$2:$D$1946 = _xlfn.MAXIFS(pivot!$D$2:$D$1946, pivot!$A$2:$A$1946, endirim!B13)), pivot!$B$2:$B$1946)} -> HasCreditCard | F13: =_xlfn.MAXIFS(pivot!$D$2:$D$1946, pivot!$A$2:$A$1946, endirim!B13) -> 65 | G13: =IF(D13=F13, "Təklif yoxdur", E13&" Kompaniyasını 20% endirimlə təklif et") -> HasCreditCard Kompaniyasını 20% endirimlə təklif et
B14: Adriena Thomton | C14: {=_xlfn.XLOOKUP(1,(pivot!$A$2:$A$1946=Table3[[#This Row],[Müştəri adı]])*(pivot!$C$2:$C$1946=_xlfn.MAXIFS(pivot!$C$2:$C$1946,pivot!$A$2:$A$1946,Table3[[#This Row],[Müştəri adı]])),pivot!$B$2:$B$1946)} -> RespondsToMailOffers | D14: {=_xlfn.XLOOKUP(1, (pivot!$A$2:$A$1946=endirim!B14) * (pivot!$C$2:$C$1946 = _xlfn.MAXIFS(pivot!$C$2:$C$1946, pivot!$A$2:$A$1946, endirim!B14)), pivot!$D$2:$D$1946)} -> 27 | E14: {=_xlfn.XLOOKUP(1, (pivot!$A$2:$A$1946=endirim!B14) * (pivot!$D$2:$D$1946 = _xlfn.MAXIFS(pivot!$D$2:$D$1946, pivot!$A$2:$A$1946, endirim!B14)), pivot!$B$2:$B$1946)} -> OptOutMailings | F14: =_xlfn.MAXIFS(pivot!$D$2:$D$1946, pivot!$A$2:$A$1946, endirim!B14) -> 75 | G14: =IF(D14=F14, "Təklif yoxdur", E14&" Kompaniyasını 20% endirimlə təklif et") -> OptOutMailings Kompaniyasını 20% endirimlə təklif et
B15: Aguie Guppy | C15: {=_xlfn.XLOOKUP(1,(pivot!$A$2:$A$1946=Table3[[#This Row],[Müştəri adı]])*(pivot!$C$2:$C$1946=_xlfn.MAXIFS(pivot!$C$2:$C$1946,pivot!$A$2:$A$1946,Table3[[#This Row],[Müştəri adı]])),pivot!$B$2:$B$1946)} -> NonUSTravel | D15: {=_xlfn.XLOOKUP(1, (pivot!$A$2:$A$1946=endirim!B15) * (pivot!$C$2:$C$1946 = _xlfn.MAXIFS(pivot!$C$2:$C$1946, pivot!$A$2:$A$1946, endirim!B15)), pivot!$D$2:$D$1946)} -> 66 | E15: {=_xlfn.XLOOKUP(1, (pivot!$A$2:$A$1946=endirim!B15) * (pivot!$D$2:$D$1946 = _xlfn.MAXIFS(pivot!$D$2:$D$1946, pivot!$A$2:$A$1946, endirim!B15)), pivot!$B$2:$B$1946)} -> NonUSTravel | F15: =_xlfn.MAXIFS(pivot!$D$2:$D$1946, pivot!$A$2:$A$1946, endirim!B15) -> 66 | G15: =IF(D15=F15, "Təklif yoxdur", E15&" Kompaniyasını 20% endirimlə təklif et") -> Təklif yoxdur
... B975: Zenia Ruecastle | C975: {=_xlfn.XLOOKUP(1,(pivot!$A$2:$A$1946=Table3[[#This Row],[Müştəri adı]])*(pivot!$C$2:$C$1946=_xlfn.MAXIFS(pivot!$C$2:$C$1946,pivot!$A$2:$A$1946,Table3[[#This Row],[Müştəri adı]])),pivot!$B$2:$B$1946)} -> NewCellphoneUser | D975: {=_xlfn.XLOOKUP(1, (pivot!$A$2:$A$1946=endirim!B975) * (pivot!$C$2:$C$1946 = _xlfn.MAXIFS(pivot!$C$2:$C$1946, pivot!$A$2:$A$1946, endirim!B975)), pivot!$D$2:$D$1946)} -> 25 | E975: {=_xlfn.XLOOKUP(1, (pivot!$A$2:$A$1946=endirim!B975) * (pivot!$D$2:$D$1946 = _xlfn.MAXIFS(pivot!$D$2:$D$1946, pivot!$A$2:$A$1946, endirim!B975)), pivot!$B$2:$B$1946)} -> OwnsComputer | F975: =_xlfn.MAXIFS(pivot!$D$2:$D$1946, pivot!$A$2:$A$1946, endirim!B975) -> 62 | G975: =IF(D975=F975, "Təklif yoxdur", E975&" Kompaniyasını 20% endirimlə təklif et") -> OwnsComputer Kompaniyasını 20% endirimlə təklif et
